Workbook

Sheet Power & Mass breakdown
A1: SYSTEM BREAKDOWN
A3: INPUTS
A4: FC gross power (nominal) | B4: 2500 | C4: kW
A5: Stack unit nominal power | B5: ='FC stacks'!B4 -> 100 | C5: kW
A6: Altitude | B6: 0 | C6: ft
A7: Ambient temperature | B7: 24 | C7: °C
A9: OUTPUTS
A10: # Stacks | B10: =B4/B5 -> 25 | C10: -
A11: System Weight | B11: =B28 -> 1991.8 | C11: kg
A12: FC net power (nominal) | B12: =B4-C28 -> 2139.9465 | C12: kW
A13: Heat rejection | B13: =B4/0.5*0.35 -> 1750 | C13: kW
A14: Hydrogen flow rate | B14: =0.000000357*B4*1000/0.65 -> 1.3730769 | C14: kg/s
A16: COMPONENTS | B16: Mass (kg) | C16: Power (kW) | D16: Volume (L)
A17: Stacks | B17: =B4/'FC stacks'!B5 -> 714.28571 | C17: - | D17: =B4/'FC stacks'!B6 -> 741.83976
A18: Compressor | B18: =SLOPE(Table4[Mass (kg)],Table4[FC gross power '[kW']])*('Power & Mass breakdown'!B4)+INTERCEPT(Table4[Mass (kg)],Table4[FC gross power '[kW']]) -> 41.037849 | C18: =SLOPE(Table4[Power (kW)],Table4[FC gross power '[kW']])*('Power & Mass breakdown'!B4)+INTERCEPT(Table4[Power (kW)],Table4[FC gross power '[kW']]) -> 263.37827 | D18: - | E18: =SLOPE(Table4[Mass (kg)],Table4[FC gross power '[kW']])*('Power & Mass breakdown'!B4)+INTERCEPT(Table4[Mass (kg)],Table4[FC gross power '[kW']]) -> 41.037849 | F18: =SLOPE(Table4[Power (kW)],Table4[FC gross power '[kW']])*('Power & Mass breakdown'!B4)+INTERCEPT(Table4[Power (kW)],Table4[FC gross power '[kW']]) -> 263.37827
A19: Humidifiers | B19: =B10*Humidifier!B16 -> 175 | C19: - | D19: =B10*Humidifier!C16 -> 325
A20: Cooling module | B20: =B4*'Cooling module'!B29 -> 450 | C20: =B10*'Cooling module'!B60 -> 17.5 | D20: -
A21: FC SYSTEM | B21: =SUM(B17:B20) -> 1380.3236 | C21: =SUM(C17:C20) -> 280.87827 | D21: =SUM(D17:D20) -> 1066.8398
A22: Power Electronics | B22: =B4/'Power electronics'!B5+'Power & Mass breakdown'!B4/'Power electronics'!B14 -> 136.47643 | C22: =(1-'Power electronics'!B6*'Power electronics'!B15)*'Power & Mass breakdown'!B4 -> 79.17525 | D22: =B4/'Power electronics'!B7+'Power & Mass breakdown'!B4/'Power electronics'!B16 -> 117.48252
A23: Valves | B23: =B10*2*('Fuel system'!B5+'Fuel system'!B9) -> 175 | C23: - | D23: -
A24: Radiators / Skin Heat Exchangers | B24: See thermal management study
A25: Tank | B25: =Tank!B20 -> 152 | C25: - | D25: =Tank!B22 -> 3000
A26: Hydrogen | B26: =Tank!B19 -> 75 | C26: N/A | D26: -
A27: H2 Piping | B27: 73 | C27: N/A | D27: -
A28: TOTAL (excl. Radiators/SHX) | B28: =SUM(B21:B23)+SUM(B25:B27) -> 1991.8 | C28: =SUM(C21:C22) -> 360.05352 | D28: =SUM(D21:D23)+SUM(D25:D27) -> 4184.3223
A30: FC System specific power | B30: =(B12)/(B21) -> 1.5503224 | C30: kW/kg
A31: BoP power / Gross power | B31: =C28/B4 -> 0.14402141
A33: Power split | B33: =B12/(2132/0.735499) -> 0.73824038
A35: OWE increase | B35: =(B28-B26)/13500 -> 0.14198518
A36: Fuel weight savings | B36: =120/43*B26 -> 209.30233 | C36: kg
A68: SPECIFIC POWER - SENSITIVITY STUDY
A70: Assumption
A71: 100 kW stacks @ 3.5kW/kg
A72: Radiators fan consumption included (estimate from AKG radiators)
A74: 1 compressor / system
A75: System Gross Power [kW] | B75: Net Power [kW] | C75: System weight [kg] | D75: Column1 | E75: Specific power [kW/kg] | F75: Efficiency
A76: 100 | B76: =Table5[[#This Row],[System Gross Power '[kW']]]*0.89 -> 89 | C76: 66 | E76: =Table5[[#This Row],[Net Power '[kW']]]/Table5[[#This Row],[System weight '[kg']]] -> 1.3484848 | F76: =Table5[[#This Row],[Net Power '[kW']]]/Table5[[#This Row],[System Gross Power '[kW']]] -> 0.89
A77: 200 | B77: =Table5[[#This Row],[System Gross Power '[kW']]]*0.89 -> 178 | C77: 120.8 | E77: =Table5[[#This Row],[Net Power '[kW']]]/Table5[[#This Row],[System weight '[kg']]] -> 1.4735099 | F77: =Table5[[#This Row],[Net Power '[kW']]]/Table5[[#This Row],[System Gross Power '[kW']]] -> 0.89
A78: 300 | B78: =Table5[[#This Row],[System Gross Power '[kW']]]*0.89 -> 267 | C78: 175.5 | E78: =Table5[[#This Row],[Net Power '[kW']]]/Table5[[#This Row],[System weight '[kg']]] -> 1.5213675 | F78: =Table5[[#This Row],[Net Power '[kW']]]/Table5[[#This Row],[System Gross Power '[kW']]] -> 0.89
A79: 400 | B79: =Table5[[#This Row],[System Gross Power '[kW']]]*0.89 -> 356 | C79: 230.3 | E79: =Table5[[#This Row],[Net Power '[kW']]]/Table5[[#This Row],[System weight '[kg']]] -> 1.5458098 | F79: =Table5[[#This Row],[Net Power '[kW']]]/Table5[[#This Row],[System Gross Power '[kW']]] -> 0.89
...

Sheet FC stacks
A1: FC STACKS
A4: Stack Max Power | B4: 100 | C4: kW
A5: Specific power | B5: 3.5 | C5: kW/kg
A6: Power density | B6: 3.37 | C6: kW/L
A10: PowerCell S3
A11: https://www.powercell.se/wordpress/wp-content/uploads/2018/12/S3-Produktblad-190430.pdf
A13: STACK S3 | B13: 49 kW | C13: 63 kW | D13: 81 kW | E13: 98 kW | F13: 125 kW
A14: Max power (kW) | B14: 49 | C14: 63 | D14: 81 | E14: 98 | F14: 125
A15: Dimensions | B15: 420x271x156 | C15: 420x321x156 | D15: 420x383x156 | E15: 420x444x156 | F15: 420x568x156
A16: Weight (kg) | B16: 21 | C16: 25 | D16: 29 | E16: 34 | F16: 43
A17: Specific Power (kW/kg) | B17: =B14/B16 -> 2.3333333 | C17: =C14/C16 -> 2.52 | D17: =D14/D16 -> 2.7931034 | E17: =E14/E16 -> 2.8823529 | F17: =F14/F16 -> 2.9069767
A18: Power Density (kW/L) | B18: =B14/(420*271*156/1000000) -> 2.759643 | C18: =C14/(420*321*156/1000000) -> 2.9954469 | D18: =D14/(420*383*156/1000000) -> 3.2278427 | E18: =E14/(420*444*156*0.000001) -> 3.3687534 | F18: =F14/(420*568*156*0.000001) -> 3.3588282
A19: Cell count | B19: 167 | C19: 215 | D19: 275 | E19: 335 | F19: 455
A20: Power/Cell | B20: =B14/B19 -> 0.29341317 | C20: =C14/C19 -> 0.29302326 | D20: =D14/D19 -> 0.29454545 | E20: =E14/E19 -> 0.29253731 | F20: =F14/F19 -> 0.27472527
A21: Acell | B21: =300/0.52 -> 576.92308 | C21: =300/0.52 -> 576.92308 | D21: =300/0.52 -> 576.92308 | E21: =300/0.52 -> 576.92308 | F21: =300/0.52 -> 576.92308
A22: Power/Area (W/m2) | B22: =B14*1000/B21/B19 -> 0.50858283 | C22: =C14*1000/C21/C19 -> 0.50790698 | D22: =D14*1000/D21/D19 -> 0.51054545 | E22: =E14*1000/E21/E19 -> 0.50706468 | F22: =F14*1000/F21/F19 -> 0.47619048
A24: STACK S2 | B24: Column1 | C24: Column2 | D24: Column3 | E24: Column4 | F24: Column5
A25: Max power (kW) | B25: 3 | C25: 6.5 | D25: 10 | E25: 26 | F25: 35.5
A26: Dimensions | B26: 490x125x155 | C26: 490x158x155 | D26: 490x192x155 | E26: 490x358x155 | F26: 490x459x155
A27: Weight (kg) | B27: 11.2 | C27: 13.7 | D27: 29 | E27: 34 | F27: 43
A28: Specific Power (kW/kg) | B28: =B25/B27 -> 0.26785714 | C28: =C25/C27 -> 0.47445255 | D28: =D25/D27 -> 0.34482759 | E28: =E25/E27 -> 0.76470588 | F28: =F25/F27 -> 0.8255814
A29: Power Density (kW/L)
A30: Cell count | B30: 24 | C30: 48 | D30: 72 | E30: 192 | F30: 264
A31: Power/Cell | B31: =B25/B30 -> 0.125 | C31: =C25/C30 -> 0.13541667 | D31: =D25/D30 -> 0.13888889 | E31: =E25/E30 -> 0.13541667 | F31: =F25/F30 -> 0.1344697
A32: Acell | B32: =120/0.52 -> 230.76923 | C32: =120/0.52 -> 230.76923 | D32: =120/0.52 -> 230.76923 | E32: =120/0.52 -> 230.76923 | F32: =120/0.52 -> 230.76923
A33: Power/Area (W/m2) | B33: =B25*1000/B30/B32 -> 0.54166667 | C33: =C25*1000/C30/C32 -> 0.58680556 | D33: =D25*1000/D30/D32 -> 0.60185185 | E33: =E25*1000/E30/E32 -> 0.58680556 | F33: =F25*1000/F30/F32 -> 0.58270202

Sheet Humidifier
A1: Membrane Humidifiers
A3: FC Stack Power | B3: 100 | C3: kW
A4: Humidifier Weight | B4: 7 | C4: kg | D4: per stack
A7: FUMATECH – Ecomate High Performance Membrane Humidifiers for Fuel Cells
A8: https://www.fumatech.com/NR/rdonlyres/0B9A1C7F-5BA6-4409-A003-5C4E79CD61AB/0/FUMATECH_BWT_GmbHMembrane_Humidifiers.pdf
A9: Fuel cell stack power (kW) | B9: Dry weight (kg) | C9: Volume (L) | D9: Specific power (kW/kg)
A10: 0.7 | B10: 0.4 | C10: 0.6 | D10: =A10/B10 -> 1.75
A11: 2 | B11: 0.6 | C11: 1 | D11: =A11/B11 -> 3.3333333
A12: 7 | B12: 3 | C12: 4 | D12: =A12/B12 -> 2.3333333
A13: 10 | B13: 3 | C13: 4 | D13: =A13/B13 -> 3.3333333
A14: 30 | B14: 5 | C14: 7 | D14: =A14/B14 -> 6
A15: 70 | B15: 6 | C15: 11 | D15: =A15/B15 -> 11.666667
A16: 110 | B16: 7 | C16: 13 | D16: =A16/B16 -> 15.714286
A37: DOE Technical Targets for Fuel Cell System Humidifiers and Air Compression Systems
A38: https://www.energy.gov/eere/fuelcells/doe-technical-targets-fuel-cell-system-humidifiers-and-air-compression-systems
A40: FC power / compressor weight ratio | B40: =80/5 -> 16 | C40: kW/kg

Sheet Compressor
A1: COMPRESSOR
A2: See Jupyter Notebooks for more information
A6: Assumptions
A7: P_1 | B7: 0.522 | C7: bar (20 000 ft)
A8: P_2 | B8: 1 | C8: bar (FC operating pressure)
A9: T_1 | B9: 21.7 | C9: °C (20 000 ft)
B11: One single compressor | D11: One compressor per stack of 100kW
A12: FC gross power [kW] | B12: Mass (kg) | C12: Power (kW) | D12: Mass n (kg) | E12: Power n (kW)
A13: 100 | B13: 12.443818 | C13: 10.535131 | D13: 12.443818 | E13: 10.535131
A14: 200 | B14: 13.635236 | C14: 21.070262 | D14: 24.887636 | E14: 21.070262
A15: 300 | B15: 14.826654 | C15: 31.605393 | D15: 37.331454 | E15: 31.605393
A16: 400 | B16: 16.018072 | C16: 42.140524 | D16: 49.775272 | E16: 42.140524
A17: 500 | B17: 17.20949 | C17: 52.675655 | D17: 62.21909 | E17: 52.675655
A18: 600 | B18: 18.400908 | C18: 63.210786 | D18: 74.662908 | E18: 63.210786
A19: 700 | B19: 19.592326 | C19: 73.745917 | D19: 87.106726 | E19: 73.745917
A20: 800 | B20: 20.783744 | C20: 84.281047 | D20: 99.550544 | E20: 84.281047
A21: 900 | B21: 21.975162 | C21: 94.816178 | D21: 111.99436 | E21: 94.816178
A22: 1000 | B22: 23.16658 | C22: 105.35131 | D22: 124.43818 | E22: 105.35131
A23: 1100 | B23: 24.357998 | C23: 115.88644 | D23: 136.882 | E23: 115.88644
A24: 1200 | B24: 25.549415 | C24: 126.42157 | D24: 149.32582 | E24: 126.42157
... A37: 2500 | B37: 41.037849 | C37: 263.37827 | D37: 311.09545 | E37: 263.37827
A39: Example
A40: FC gross power | B40: 2000 | C40: kW
A41: Compressor weight | B41: =SLOPE(B13:B37,A13:A37)*B40+INTERCEPT(B13:B37,A13:A37) -> 35.080759 | C41: kg | D41: (1 compressor/system)
A42: Power consumption | B42: =SLOPE(C13:C37,A13:A37)*B40+INTERCEPT(C13:C37,A13:A37) -> 210.70262 | C42: kW | D42: (1 compressor/system)
A46: Model verification - 100 kW stack
A48: Hypothesis
A49: Stack power | B49: 100 | C49: kW
A50: Number compressors | B50: 1 | C50: /stack
A51: Pressure ratio | B51: 2
A54: Outputs
A55: Flow rate | B55: =0.11*1000 -> 110 | C55: g/s | D55: See Python Model
A56: Power consumption | B56: 11.1 | C56: kW | D56: See Python Model
A58: Mass (kg) | B58: 12.6 | C58: Mass model 1
B59: 10 | C59: INN-BALANCE project / Celeroton turbo-compressors (100 kW Fuel Cell)
B60: 15 | C60: DOE technical targets 2020 (80 kW Fuel Cell)
B61: 8.5 | C61: Fischer EMTCT-120k - Swiss hydrogen 100kW FCS study
A62: Average mass (kg) | B62: =AVERAGE(B58:B61) -> 11.525
A64: Volume (L) | B64: =400*220*80*0.000001 -> 7.04 | C64: Fischer EMTCT-120k - Swiss hydrogen 100kW FCS study
B65: =310.7*154.4*191.5*0.000001 -> 9.1866533 | C65: INN-BALANCE project / Celeroton turbo-compressors (100 kW Fuel Cell)
...

Sheet Power electronics
A1: Inverter
A2: A 50-kW High-Frequency and High-Efficiency SiC Voltage Source Inverter for More Electric Aircraft
A3: https://www.researchgate.net/publication/316445819_A_50-kW_High-Frequency_and_High-Efficiency_SiC_Voltage_Source_Inverter_for_More_Electric_Aircraft
A5: Specific power | B5: 26 | C5: kW/kg | E5: Vincenzo: 11 kW/kg ?
A6: Efficiency | B6: 0.9791
A7: Power density | B7: 25 | C7: kW/L
A10: DC-DC converter
A11: Bidirectional full SiC 200 kW DC-DC Converter for Electric, Hybrid and Fuel Cell Vehicles
A12: https://www.mikroelektronik.fraunhofer.de/content/dam/mikroelektronik/Datenbltter/IISB_200kW-Rekordwandler_DB.pdf
A14: Specific power | B14: 62 | C14: kW/kg
A15: Efficiency | B15: 0.989
A16: Power density | B16: 143 | C16: kW/L
A36: Additional data for DC-DC converter:
A37: Design Considerations for the Electrical Power Supply of Future Civil Aircraft with Active High-Lift Systems, J.K. Mueller 2018
A38: https://pdfs.semanticscholar.org/4671/ac994b57735012d85c9bb01cbc4b4e5c36a9.pdf
A40: Specific power | B40: =1/0.016 -> 62.5 | C40: kW/kg
A41: Efficiency | B41: 0.98

Sheet Fuel system
A1: VALVES AND REGULATORS
A3: CRYOPLANE STUDY
A4: Valve (shut-off function)
A5: Weight | B5: 1 | C5: kg
A6: Dimensions | B6: 50x50x50 | C6: mm
A8: Actuators (regulating functions)
A9: Weight | B9: 2.5 | C9: kg | D9: (2-3 kg depending on the complexity)
A13: PIPES
A14: See Python Notebook
A15: S:\ENGINEERING\CUSTOMIZED_ENGINEERING\PRELIM_DESIGN_INTERNSHIPS\2020_F_Pollet\PART IV - MODELISATIONS\Feeding Lines
A18: CRYO-PUMPS
A19: NO DATA

Sheet Tank
A1: TANK
A3: Python Notebook
A4: S:\ENGINEERING\CUSTOMIZED_ENGINEERING\PRELIM_DESIGN_INTERNSHIPS\2020_F_Pollet\PART IV - MODELISATIONS
A6: INPUTS
A7: Required Energy | B7: 9000 | C7: MJ
A8: Geometry | B8: Ellipsoide | C8: (psi=phi=1, lambda=0.7)
A9: Venting pressure | B9: 4 | C9: bar
A10: Filling pressure | B10: 2 | C10: bar
A11: Wall tank material | B11: Stainless steel
A12: Insulation | B12: Rohacell foam
A13: Insulation thickness | B13: 3 | C13: cm
A14: H2 Temperature | B14: 22 | C14: K
A15: Ambient Temperature | B15: 273 | C15: K
A18: OUTPUTS
A19: Mass hydrogen | B19: 75 | C19: kg
A20: Mass empty tank | B20: 152 | C20: kg | D20: 135kg wall + 17kg insulation
A21: Gravimetric efficiency | B21: =B19/(B19+B20) -> 0.33039648
A22: Tank volume | B22: 3000 | C22: L
A23: Length | B23: 2.4 | C23: m
A24: Diameter | B24: =0.5182*2 -> 1.0364 | C24: m
A25: Heat flux | B25: 10.5 | C25: W
A26: Boil-off | B26: 2 | C26: kg/day

Sheet Cooling module
A1: COOLING SYSTEM
A2: Thermal Management of PEM Fuel Cells in Electric Vehicles
A3: Michael Nöst, Christian Doppler, Manfred Klell and Alexander Trattner
A4: 2018
A27: 1 - COOLING MODULE WEIGHT DATA
A29: WEIGHT-POWER RATIO SELECTED VALUE | B29: 0.18 | C29: kg/kW
A32: INN-BALANCE PROJECT | B32: D1.4 – Public results of the architecture and system level optimization
A33: FC power (gross) | B33: 100 | C33: kW | I33: 6.5 | J33: 2
A34: FC power (net) | B34: 89 | C34: kW | I34: 11.8 | J34: 7.5
A35: Cooling module weight | B35: 17.2 | C35: kg | I35: 19.9 | J35: 230
A36: weight-power ratio | B36: =B35/B33 -> 0.172 | C36: kg/kW | E36: =B33/B35 -> 5.8139535 | I36: 24 | J36: 165
A38: AVACON | B38: ASSESSMENT OF A FUEL CELL POWERED FULL ELECTRIC SUBSYSTEM ARCHITECTURE FOR THE AVACON RESEARCH BASELINE AIRCRAFT, 2019
A39: FC power (gross) | B39: 600 | C39: kW
A40: FC power (net) | B40: 500 | C40: kW
A41: Cooling module weight | B41: 110 | C41: kg
A42: weight-power ratio | B42: =B41/B39 -> 0.18333333 | C42: kg/kW
A45: 2 - PUMP POWER SIZING
A46: Python Notebook (WIP)
A47: Heat exchanger
A49: Hypothesis | B49: Derived from Vratny "Conceptual Design Methods of Electric Power Architectures for Hybrid Energy Aircraft"
A50: Stack power | B50: 100 | C50: kW
A51: Coolant inlet Temp. | B51: 70 | C51: °C
A52: Coolant outlet Temp. | B52: 80 | C52: °C
A53: Pressure drop | B53: 2 | C53: bar
A54: Coolant specific heat | B54: 3200 | C54: J/kg/K | D54: Potassium formate/water 40:60 wt
A55: Coolant density | B55: 1250 | C55: kg/m3
A56: Safety factor | B56: 1.2 | C56: uncertainties
A58: Python Outputs
A59: Heat flow | B59: 92.3 | C59: kW
A60: Elec. Power consumption | B60: 0.7 | C60: kW | D60: per stack
A63: 3 - Hydrogen Heat Sink potential
A64: H2 heat sink
A65: FC power | B65: ='Power & Mass breakdown'!B4 -> 2500 | C65: kW
A66: m_dot | B66: =0.0000000105*B65*1000/0.65 -> 0.040384615 | C66: kg/s
A67: he | B67: =461 -> 461 | C67: kJ/kg
A68: cp | B68: 15 | C68: kJ/kg/K
A69: T_1 | B69: 20 | C69: K
A70: T_2 | B70: =273.15+80 -> 353.15 | C70: K
A71: q_H2 | B71: =B66*B67+B66*B68*(B70-B69) -> 220.42933 | C71: kW
A72: % of the waste heat | B72: =B71/SHX_old!B7 -> 0.12595962

Sheet Layouts

Sheet Cooling_old
A1: COOLING SYSTEM
A3: 1 - RADIATOR WEIGHT DATA
B4: https://www.akg-group.com/fileadmin/user_upload/Brochures/AKG-Line/AKG_LineA_en.pdf
A5: AKG-Line Radiator with fan | B5: https://www.akg-group.com/fileadmin/user_upload/Brochures/AKG-Line/AKG_LineH_en.pdf | AP5: 0
A6: Product | B6: H50/A35 | C6: H80/A60 | D6: H110/A75 | E6: H150/A105 | F6: H175/A120 | G6: H200/A135 | H6: H320/A225 | I6: H490/A330
A7: Max. Specific heat rejection (kW/K) | B7: 0.93 | C7: 1.38 | D7: 1.85 | E7: 2.7 | F7: 3 | G7: 3.4 | H7: 5.55 | I7: 8.2
A8: Max. oil flow (l/min) | B8: 250 | C8: 350 | D8: 500 | E8: 700 | F8: 700 | G8: 700 | H8: 800 | I8: 950
A9: Coolant temperature (°C) | B9: 75
A10: Delta Temperature (K) | B10: =B9-'Power & Mass breakdown'!B7 -> 51
A11: Max. heat rejection (kW) | B11: =B7*$B$10 -> 47.43 | C11: =C7*$B$10 -> 70.38 | D11: =D7*$B$10 -> 94.35 | E11: =E7*$B$10 -> 137.7 | F11: =F7*$B$10 -> 153 | G11: =G7*$B$10 -> 173.4 | H11: =H7*$B$10 -> 283.05 | I11: =I7*$B$10 -> 418.2
A12: Weight (kg) - with hydraulic motor | B12: 35 | C12: 61 | D12: 73 | E12: 87 | F12: 115 | G12: 135 | H12: 180 | I12: 232
A13: Weight (kg) - with AC motor | B13: 43 | C13: 69 | D13: 81 | E13: 100 | F13: 128 | G13: 148 | H13: 217 | I13: 343
A14: Volume (L) - radiator only | B14: =0.601*0.7*0.18/2*1000 -> 37.863 | C14: =0.666*0.79*0.24/2*1000 -> 63.1368 | D14: =0.791*0.94*0.34/2*1000 -> 126.4018 | E14: =0.884*0.99*0.34/2*1000 -> 148.7772 | F14: =0.992*1.04*0.41/2*1000 -> 211.4944 | G14: =0.989*1.09*0.41/2*1000 -> 220.99205 | H14: =1.22*1.24*0.41/2*1000 -> 310.124 | I14: =1.524*1.34*0.41/2*1000 -> 418.6428
A15: Frontal area (m2) | B15: =0.601*0.7 -> 0.4207 | C15: =0.666*0.79 -> 0.52614 | D15: =0.791*0.94 -> 0.74354 | E15: =0.884*0.99 -> 0.87516 | F15: =0.992*1.04 -> 1.03168 | G15: =0.989*1.09 -> 1.07801 | H15: =1.22*1.24 -> 1.5128 | I15: =1.524*1.34 -> 2.04216
A16: Power consumption (kW) - AC motor | B16: 0.75 | C16: 0.75 | D16: 0.75 | E16: 2.2 | F16: 2.2 | G16: 2.2 | H16: 5.5 | I16: 11
A17: AC Motor & brackets weight (scaling law m = 3*P^1.5) | B17: =3*B16^(3/2) -> 1.9485572 | C17: =3*C16^(3/2) -> 1.9485572 | D17: =3*D16^(3/2) -> 1.9485572 | E17: =3*E16^(3/2) -> 9.789382 | F17: =3*F16^(3/2) -> 9.789382 | G17: =3*G16^(3/2) -> 9.789382 | H17: =3*H16^(3/2) -> 38.69593 | I17: =3*I16^(3/2) -> 109.44862
A18: Cooling-mass ratio [kW/kg] | B18: =B11/B12 -> 1.3551429 | C18: =C11/C13 -> 1.02 | D18: =D11/D13 -> 1.1648148 | E18: =E11/E13 -> 1.377 | F18: =F11/F13 -> 1.1953125 | G18: =G11/G13 -> 1.1716216 | H18: =H11/H13 -> 1.3043779 | I18: =I11/I13 -> 1.219242
B19: =(B13-B12)/B13 -> 0.18604651 | C19: =(C13-C12)/C13 -> 0.11594203 | D19: =(D13-D12)/D13 -> 0.098765432 | E19: =(E13-E12)/E13 -> 0.13 | F19: =(F13-F12)/F13 -> 0.1015625 | G19: =(G13-G12)/G13 -> 0.087837838 | H19: =(H13-H12)/H13 -> 0.17050691 | I19: =(I13-I12)/I13 -> 0.32361516
A20: Number of radiators (input) | B20: 10
A21: RADIATOR WEIGHT (unit / total) | B21: =SLOPE(B12:I12,B11:I11)*('Power & Mass breakdown'!B13/B20)+INTERCEPT(B12:I12,B11:I11) -> 116.22295 | C21: =B20*B21 -> 1162.2295 | D21: kg | F21: Available cross section area - bellyfairing
A22: RADIATOR VOLUME (unit / total) | B22: =SLOPE(B14:I14,B11:I11)*('Power & Mass breakdown'!B13/B20)+INTERCEPT(B14:I14,B11:I11) -> 195.01932 | C22: =B20*B22 -> 1950.1932 | D22: l | F22: < 4 m2
A23: FRONTAL AREA (unit / total) | B23: =SLOPE(B15:I15,B11:I11)*('Power & Mass breakdown'!B13/B20)+INTERCEPT(B15:I15,B11:I11) -> 1.0408663 | C23: =B20*B23 -> 10.408663 | D23: m2
A24: FAN MOTOR CONSUMPTION (unit / total) | B24: =('Power & Mass breakdown'!B13/B20)/I11*I16 -> 4.6030607 | C24: =B20*B24 -> 46.030607 | D24: kW | F24: =SLOPE(B8:I8,B11:I11)*('Power & Mass breakdown'!B13/B20)+INTERCEPT(B8:I8,B11:I11) -> 623.50586 | G24: =F24*B20 -> 6235.0586
A25: HEAT REJECTION (unit / total) | B25: ='Power & Mass breakdown'!B13/Cooling_old!B20 -> 175 | C25: =B20*B25 -> 1750 | D25: kW
A28: 2 - COOLING MODULE WEIGHT DATA
A30: WEIGHT-POWER RATIO SELECTED VALUE | B30: 0.18 | C30: kg/kW
A33: INN-BALANCE PROJECT | B33: D1.4 – Public results of the architecture and system level optimization
A34: FC power (gross) | B34: 100 | C34: kW | I34: 6.5 | J34: 2
A35: FC power (net) | B35: 89 | C35: kW | I35: 11.8 | J35: 7.5
A36: Cooling module weight | B36: 17.2 | C36: kg | I36: 19.9 | J36: 230
A37: weight-power ratio | B37: =B36/B34 -> 0.172 | C37: kg/kW | E37: =B34/B36 -> 5.8139535 | I37: 24 | J37: 165
A39: AVACON | B39: ASSESSMENT OF A FUEL CELL POWERED FULL ELECTRIC SUBSYSTEM ARCHITECTURE FOR THE AVACON RESEARCH BASELINE AIRCRAFT, 2019
A40: FC power (gross) | B40: 600 | C40: kW
A41: FC power (net) | B41: 500 | C41: kW
A42: Cooling module weight | B42: 110 | C42: kg
A43: weight-power ratio | B43: =B42/B40 -> 0.18333333 | C43: kg/kW
A47: 3 - PUMP POWER SIZING
A48: Python Notebook (WIP)
A49: Heat exchanger
A51: Hypothesis | B51: Derived from Vratny "Conceptual Design Methods of Electric Power Architectures for Hybrid Energy Aircraft"
...

Sheet SHX_old
A1: SKIN HEAT EXCHANGERS
A2: S:\ENGINEERING\CUSTOMIZED_ENGINEERING\PRELIM_DESIGN_INTERNSHIPS\2020_F_Pollet\1 - DOCUMENTS\THERMAL MANAGEMENT\Skin Heat
A3: Cooling Ability/Capacity and Exergy Penalty Analysis of Each Heat Sink of Modern Supersonic Aircraft, Mao 2019
A4: Cours ISAE – Systèmes d'Air Electriques - Janvier 2020 - D. LAVERGNE, LIEBHERR
A6: Cooling required
A7: Q_req | B7: ='Power & Mass breakdown'!B13 -> 1750 | C7: kW | I7: Stefan-Boltzmann constant | J7: 5.67e-08 | K7: W/m2/K
A9: Operating conditions | I9: Thermo-aero parameters
A10: Altitude | B10: 20000 | C10: ft | I10: Thermal conductivity air | J10: 0.02436 | K10: W/m/K
A11: T_stat (OAT) | B11: =[1]!Tstatic(B10*0.3048,25) -> #NAME? | C11: K | D11: Hot day, ISA+25 | I11: Reynolds | J11: =[1]!Reynolds(B12,B13,B11) -> #NAME?
A12: Mach max | B12: 0.45 | I12: Prandtl | J12: 0.71
A13: P_stat | B13: =[1]!Pstatic(B10*0.3048) -> #NAME? | C13: Pa | I13: Nusselt (turbulent flow) | J13: =(0.037*J11^0.8*J12)/(1+2.443*J11^(-0.1)*(J12^(2/3)-1)) -> #NAME? | K13: Petukov (High Temperature I, 1963) and Schlichting (Grenzschicht-Theorie, 1958).
A14: T_tot | B14: =[1]!Ttotal(B11,B12) -> #NAME? | C14: K | I14: Nusselt (laminar flow) | J14: =0.332*J11^0.5*J12^(1/3) -> #NAME? | K14: https://www.tec-science.com/mechanics/gases-and-liquids/calculation-of-the-nusselt-numbers-for-forced-flows-over-plates-and-in-pipes/
A16: Skin heat transfer
A17: T_load | B17: =70+273.15 -> 343.15 | C17: K | D17: heat exchanger temperature, coolant side
A18: eta_shx | B18: 0.8 | D18: skin heat transfer efficiency
A19: T_skin | B19: =B14+B18*(B17-B14) -> #NAME? | C19: K | D19: heat exchanger temperature, air side
A20: h_shx | B20: =J13*J10 -> #NAME? | C20: W/m2/K | D20: outside convective coefficient
A21: e_skin | B21: 0.7 | D21: skin emissivity
A22: q_shx | B22: =B20*(B19-B14)+J7*B21*(B19^4-B11^4) -> #NAME? | C22: W/m2
A24: Radiation power
A25: q_rad | B25: =1135+240*B10/40000 -> 1255 | C25: W/m2
A27: Skin heat exchanger geometry
A28: A_skin | B28: =B7*1000/(B22-B25/2) -> #NAME? | C28: m2 | D28: skin surface
A29: m x c | B29: =B7/(B17-B19) -> #NAME? | C29: kW/K | D29: coolant thermal flow rate
A30: A_eff | B30: =-B29*1000*LN(1-B18)/B20 -> #NAME? | C30: m2 | D30: effective heat transfer area (between coolant and skin)
A31: alpha | B31: 600 | C31: m2/m3 | D31: surface area density
A32: rho_shx | B32: 300 | C32: kg/m3 | D32: mass density
A33: m_shx | B33: =B32*B30/B31 -> #NAME? | C33: kg
A35: SENSITIVITY STUDY
A37: FC gross power [kW] | B37: Q_req [kW] | C37: Eta_shx | D37: A_skin [m2] | E37: m_shx [kg] | F37: Cooling-mass ratio [kW/kg] | G37: Cooling-area ratio [kW/m2]
A38: 1800 | B38: 1260 | C38: 0.5 | D38: 283.6 | E38: 88.98 | F38: =Table3[[#This Row],[Q_req '[kW']]]/Table3[[#This Row],[m_shx '[kg']]] -> 14.160486 | G38: =Table3[[#This Row],[Q_req '[kW']]]/Table3[[#This Row],[A_skin '[m2']]] -> 4.4428773
A39: 1800 | B39: 1260 | C39: 0.6 | D39: 231 | E39: 147.02 | F39: =Table3[[#This Row],[Q_req '[kW']]]/Table3[[#This Row],[m_shx '[kg']]] -> 8.5702625 | G39: =Table3[[#This Row],[Q_req '[kW']]]/Table3[[#This Row],[A_skin '[m2']]] -> 5.4545455
A40: 1800 | B40: 1260 | C40: 0.7 | D40: 194.8 | E40: 257.58 | F40: =Table3[[#This Row],[Q_req '[kW']]]/Table3[[#This Row],[m_shx '[kg']]] -> 4.8916841 | G40: =Table3[[#This Row],[Q_req '[kW']]]/Table3[[#This Row],[A_skin '[m2']]] -> 6.4681725
A41: 1800 | B41: 1260 | C41: 0.8 | D41: 168.4 | E41: 516.49 | F41: =Table3[[#This Row],[Q_req '[kW']]]/Table3[[#This Row],[m_shx '[kg']]] -> 2.4395438 | G41: =Table3[[#This Row],[Q_req '[kW']]]/Table3[[#This Row],[A_skin '[m2']]] -> 7.4821853
A42: 1800 | B42: 1260 | C42: 0.9 | D42: 148.3 | E42: 1477.85 | F42: =Table3[[#This Row],[Q_req '[kW']]]/Table3[[#This Row],[m_shx '[kg']]] -> 0.85258991 | G42: =Table3[[#This Row],[Q_req '[kW']]]/Table3[[#This Row],[A_skin '[m2']]] -> 8.4962913
A58: Misc.
A60: Sakuma2017
A61: L | B61: =900/1000 -> 0.9
A62: s | B62: =4/1000 -> 0.004
A63: H | B63: =25/1000 -> 0.025
...
